{"kind":"symbol","primaryContentSections":[{"kind":"declarations","declarations":[{"languages":["swift"],"platforms":["iOS"],"tokens":[{"kind":"keyword","text":"let"},{"text":" ","kind":"text"},{"kind":"identifier","text":"error"},{"kind":"text","text":": "},{"identifier":"doc:\/\/digimecore.DigiMeCore\/documentation\/DigiMeCore\/SyncError","text":"SyncError","preciseIdentifier":"s:10DigiMeCore9SyncErrorV","kind":"typeIdentifier"},{"text":"?","kind":"text"}]}]}],"abstract":[{"text":"An error giving details of the reason synchronization failed.","type":"text"},{"text":" ","type":"text"},{"type":"text","text":"Only available for ‘partial’ synchronization state"}],"schemaVersion":{"patch":0,"minor":3,"major":0},"identifier":{"interfaceLanguage":"swift","url":"doc:\/\/digimecore.DigiMeCore\/documentation\/DigiMeCore\/SyncAccount\/error"},"hierarchy":{"paths":[["doc:\/\/digimecore.DigiMeCore\/documentation\/DigiMeCore","doc:\/\/digimecore.DigiMeCore\/documentation\/DigiMeCore\/SyncAccount"]]},"variants":[{"paths":["\/documentation\/digimecore\/syncaccount\/error"],"traits":[{"interfaceLanguage":"swift"}]}],"sections":[],"metadata":{"modules":[{"name":"DigiMeCore"}],"role":"symbol","roleHeading":"Instance Property","externalID":"s:10DigiMeCore11SyncAccountV5errorAA0D5ErrorVSgvp","fragments":[{"kind":"keyword","text":"let"},{"kind":"text","text":" "},{"kind":"identifier","text":"error"},{"kind":"text","text":": "},{"kind":"typeIdentifier","preciseIdentifier":"s:10DigiMeCore9SyncErrorV","text":"SyncError"},{"text":"?","kind":"text"}],"title":"error","symbolKind":"property"},"references":{"doc://digimecore.DigiMeCore/documentation/DigiMeCore/SyncAccount":{"identifier":"doc:\/\/digimecore.DigiMeCore\/documentation\/DigiMeCore\/SyncAccount","url":"\/documentation\/digimecore\/syncaccount","title":"SyncAccount","type":"topic","abstract":[{"type":"text","text":"Details of a source being synchronized"}],"fragments":[{"text":"struct","kind":"keyword"},{"text":" ","kind":"text"},{"kind":"identifier","text":"SyncAccount"}],"kind":"symbol","navigatorTitle":[{"text":"SyncAccount","kind":"identifier"}],"role":"symbol"},"doc://digimecore.DigiMeCore/documentation/DigiMeCore":{"role":"collection","title":"DigiMeCore","url":"\/documentation\/digimecore","abstract":[],"kind":"symbol","identifier":"doc:\/\/digimecore.DigiMeCore\/documentation\/DigiMeCore","type":"topic"},"doc://digimecore.DigiMeCore/documentation/DigiMeCore/SyncAccount/error":{"kind":"symbol","abstract":[{"type":"text","text":"An error giving details of the reason synchronization failed."},{"type":"text","text":" "},{"type":"text","text":"Only available for ‘partial’ synchronization state"}],"role":"symbol","url":"\/documentation\/digimecore\/syncaccount\/error","fragments":[{"kind":"keyword","text":"let"},{"kind":"text","text":" "},{"kind":"identifier","text":"error"},{"kind":"text","text":": "},{"text":"SyncError","kind":"typeIdentifier","preciseIdentifier":"s:10DigiMeCore9SyncErrorV"},{"text":"?","kind":"text"}],"identifier":"doc:\/\/digimecore.DigiMeCore\/documentation\/DigiMeCore\/SyncAccount\/error","type":"topic","title":"error"},"doc://digimecore.DigiMeCore/documentation/DigiMeCore/SyncError":{"identifier":"doc:\/\/digimecore.DigiMeCore\/documentation\/DigiMeCore\/SyncError","role":"symbol","kind":"symbol","title":"SyncError","url":"\/documentation\/digimecore\/syncerror","navigatorTitle":[{"kind":"identifier","text":"SyncError"}],"fragments":[{"text":"struct","kind":"keyword"},{"text":" ","kind":"text"},{"text":"SyncError","kind":"identifier"}],"abstract":[{"text":"Reason why connecting to source or importing data from source into user’s library failed","type":"text"}],"type":"topic"}}}