{"hierarchy":{"paths":[["doc:\/\/digimecore.DigiMeCore\/documentation\/DigiMeCore","doc:\/\/digimecore.DigiMeCore\/documentation\/DigiMeCore\/SyncAccount"]]},"kind":"symbol","primaryContentSections":[{"declarations":[{"platforms":["iOS"],"languages":["swift"],"tokens":[{"text":"let","kind":"keyword"},{"text":" ","kind":"text"},{"text":"error","kind":"identifier"},{"text":": ","kind":"text"},{"text":"SyncError","preciseIdentifier":"s:10DigiMeCore9SyncErrorV","kind":"typeIdentifier","identifier":"doc:\/\/digimecore.DigiMeCore\/documentation\/DigiMeCore\/SyncError"},{"kind":"text","text":"?"}]}],"kind":"declarations"}],"variants":[{"traits":[{"interfaceLanguage":"swift"}],"paths":["\/documentation\/digimecore\/syncaccount\/error"]}],"schemaVersion":{"minor":3,"major":0,"patch":0},"identifier":{"url":"doc:\/\/digimecore.DigiMeCore\/documentation\/DigiMeCore\/SyncAccount\/error","interfaceLanguage":"swift"},"abstract":[{"type":"text","text":"An error giving details of the reason synchronization failed."},{"type":"text","text":" "},{"type":"text","text":"Only available for ‘partial’ synchronization state"}],"sections":[],"metadata":{"externalID":"s:10DigiMeCore11SyncAccountV5errorAA0D5ErrorVSgvp","title":"error","role":"symbol","roleHeading":"Instance Property","symbolKind":"property","fragments":[{"text":"let","kind":"keyword"},{"text":" ","kind":"text"},{"kind":"identifier","text":"error"},{"kind":"text","text":": "},{"text":"SyncError","preciseIdentifier":"s:10DigiMeCore9SyncErrorV","kind":"typeIdentifier"},{"kind":"text","text":"?"}],"modules":[{"name":"DigiMeCore"}]},"references":{"doc://digimecore.DigiMeCore/documentation/DigiMeCore/SyncAccount":{"abstract":[{"text":"Details of a source being synchronized","type":"text"}],"role":"symbol","kind":"symbol","title":"SyncAccount","url":"\/documentation\/digimecore\/syncaccount","identifier":"doc:\/\/digimecore.DigiMeCore\/documentation\/DigiMeCore\/SyncAccount","type":"topic","navigatorTitle":[{"kind":"identifier","text":"SyncAccount"}],"fragments":[{"text":"struct","kind":"keyword"},{"text":" ","kind":"text"},{"text":"SyncAccount","kind":"identifier"}]},"doc://digimecore.DigiMeCore/documentation/DigiMeCore":{"url":"\/documentation\/digimecore","abstract":[],"role":"collection","identifier":"doc:\/\/digimecore.DigiMeCore\/documentation\/DigiMeCore","kind":"symbol","title":"DigiMeCore","type":"topic"},"doc://digimecore.DigiMeCore/documentation/DigiMeCore/SyncAccount/error":{"identifier":"doc:\/\/digimecore.DigiMeCore\/documentation\/DigiMeCore\/SyncAccount\/error","kind":"symbol","role":"symbol","abstract":[{"text":"An error giving details of the reason synchronization failed.","type":"text"},{"type":"text","text":" "},{"text":"Only available for ‘partial’ synchronization state","type":"text"}],"title":"error","fragments":[{"kind":"keyword","text":"let"},{"text":" ","kind":"text"},{"text":"error","kind":"identifier"},{"kind":"text","text":": "},{"text":"SyncError","kind":"typeIdentifier","preciseIdentifier":"s:10DigiMeCore9SyncErrorV"},{"text":"?","kind":"text"}],"url":"\/documentation\/digimecore\/syncaccount\/error","type":"topic"},"doc://digimecore.DigiMeCore/documentation/DigiMeCore/SyncError":{"type":"topic","role":"symbol","title":"SyncError","fragments":[{"kind":"keyword","text":"struct"},{"kind":"text","text":" "},{"text":"SyncError","kind":"identifier"}],"url":"\/documentation\/digimecore\/syncerror","identifier":"doc:\/\/digimecore.DigiMeCore\/documentation\/DigiMeCore\/SyncError","kind":"symbol","abstract":[{"text":"Reason why connecting to source or importing data from source into user’s library failed","type":"text"}],"navigatorTitle":[{"text":"SyncError","kind":"identifier"}]}}}