{"primaryContentSections":[{"kind":"declarations","declarations":[{"platforms":["iOS"],"languages":["swift"],"tokens":[{"text":"let","kind":"keyword"},{"text":" ","kind":"text"},{"kind":"identifier","text":"reauth"},{"kind":"text","text":": "},{"kind":"typeIdentifier","preciseIdentifier":"s:Sb","text":"Bool"},{"text":"?","kind":"text"}]}]}],"kind":"symbol","sections":[],"variants":[{"traits":[{"interfaceLanguage":"swift"}],"paths":["\/documentation\/digimecore\/syncerror\/reauth"]}],"metadata":{"roleHeading":"Instance Property","fragments":[{"kind":"keyword","text":"let"},{"kind":"text","text":" "},{"kind":"identifier","text":"reauth"},{"text":": ","kind":"text"},{"text":"Bool","kind":"typeIdentifier","preciseIdentifier":"s:Sb"},{"text":"?","kind":"text"}],"role":"symbol","externalID":"s:10DigiMeCore9SyncErrorV6reauthSbSgvp","symbolKind":"property","modules":[{"name":"DigiMeCore"}],"title":"reauth"},"identifier":{"url":"doc:\/\/digimecore.DigiMeCore\/documentation\/DigiMeCore\/SyncError\/reauth","interfaceLanguage":"swift"},"hierarchy":{"paths":[["doc:\/\/digimecore.DigiMeCore\/documentation\/DigiMeCore","doc:\/\/digimecore.DigiMeCore\/documentation\/DigiMeCore\/SyncError"]]},"schemaVersion":{"major":0,"minor":3,"patch":0},"references":{"doc://digimecore.DigiMeCore/documentation/DigiMeCore":{"role":"collection","title":"DigiMeCore","url":"\/documentation\/digimecore","abstract":[],"kind":"symbol","identifier":"doc:\/\/digimecore.DigiMeCore\/documentation\/DigiMeCore","type":"topic"},"doc://digimecore.DigiMeCore/documentation/DigiMeCore/SyncError":{"identifier":"doc:\/\/digimecore.DigiMeCore\/documentation\/DigiMeCore\/SyncError","role":"symbol","kind":"symbol","title":"SyncError","url":"\/documentation\/digimecore\/syncerror","navigatorTitle":[{"kind":"identifier","text":"SyncError"}],"fragments":[{"text":"struct","kind":"keyword"},{"text":" ","kind":"text"},{"text":"SyncError","kind":"identifier"}],"abstract":[{"text":"Reason why connecting to source or importing data from source into userâ€™s library failed","type":"text"}],"type":"topic"},"doc://digimecore.DigiMeCore/documentation/DigiMeCore/SyncError/reauth":{"kind":"symbol","url":"\/documentation\/digimecore\/syncerror\/reauth","fragments":[{"kind":"keyword","text":"let"},{"text":" ","kind":"text"},{"text":"reauth","kind":"identifier"},{"text":": ","kind":"text"},{"text":"Bool","kind":"typeIdentifier","preciseIdentifier":"s:Sb"},{"text":"?","kind":"text"}],"role":"symbol","type":"topic","title":"reauth","identifier":"doc:\/\/digimecore.DigiMeCore\/documentation\/DigiMeCore\/SyncError\/reauth","abstract":[]}}}